Workbook
Name Slicer_Region: #N/A
Name Slicer_Segment: #N/A
Name Slicer_Year: #N/A

Sheet Combo chart
A3: Row Labels | B3: Sum of Sales | C3: Sum of Profit
A4: Jan | B4: 11074.039 | C4: 2512.7053
A5: Feb | B5: 1494.19 | C5: -840.3093
A6: Mar | B6: 8879.398 | C6: 1092.1587
A7: Apr | B7: 2047.026 | C7: 84.5482
A8: May | B8: 4069.0664 | C8: 438.6879
A9: Jun | B9: 2818.0252 | C9: 39.9082
A10: Jul | B10: 2407.508 | C10: 317.1642
A11: Aug | B11: 3083.242 | C11: 530.3111
A12: Sep | B12: 5556.877 | C12: -266.2098
A13: Oct | B13: 6455.6352 | C13: 530.1614
A14: Nov | B14: 6664.5738 | C14: -2489.0796
A15: Dec | B15: 13796.095 | C15: 1030.6896
A16: Grand Total | B16: 68345.675 | C16: 2980.7359

Sheet WaterFall Chart
A3: Row Labels | B3: Sum of Profit | D3: Category | E3: Profit
A4: Technology | B4: 2975.6517 | D4: =A4 -> Technology | E4: =GETPIVOTDATA("Profit",$A$3,"Category",A4) -> 2975.6517
A5: Office Supplies | B5: 1384.9375 | D5: =A5 -> Office Supplies | E5: =GETPIVOTDATA("Profit",$A$3,"Category",A5) -> 1384.9375
A6: Furniture | B6: -1379.8533 | D6: =A6 -> Furniture | E6: =GETPIVOTDATA("Profit",$A$3,"Category",A6) -> -1379.8533
A7: Grand Total | B7: 2980.7359 | D7: =A7 -> Grand Total | E7: =GETPIVOTDATA("Profit",$A$3) -> 2980.7359

Sheet Pie Chart
A3: Row Labels | B3: Sum of Sales
A4: Furniture | B4: 0.35738562
A5: Office Supplies | B5: 0.41606065
A6: Technology | B6: 0.22655373
A7: Grand Total | B7: 1

Sheet Map Chart
A3: Row Labels | B3: Sum of Sales | D3: State | E3: Sales
A4: Illinois | B4: 10945.574 | D4: =A4 -> Illinois | E4: =GETPIVOTDATA("Sales",$A$3,"State",A4) -> 10945.574
A5: Indiana | B5: 4985.88 | D5: =A5 -> Indiana | E5: =GETPIVOTDATA("Sales",$A$3,"State",A5) -> 4985.88
A6: Iowa | B6: 257.19 | D6: =A6 -> Iowa | E6: =GETPIVOTDATA("Sales",$A$3,"State",A6) -> 257.19
A7: Kansas | B7: 279.9 | D7: =A7 -> Kansas | E7: =GETPIVOTDATA("Sales",$A$3,"State",A7) -> 279.9
A8: Michigan | B8: 11758.61 | D8: =A8 -> Michigan | E8: =GETPIVOTDATA("Sales",$A$3,"State",A8) -> 11758.61
A9: Minnesota | B9: 4407.6 | D9: =A9 -> Minnesota | E9: =GETPIVOTDATA("Sales",$A$3,"State",A9) -> 4407.6
A10: Missouri | B10: 2279.77 | D10: =A10 -> Missouri | E10: =GETPIVOTDATA("Sales",$A$3,"State",A10) -> 2279.77
A11: Nebraska | B11: 2620.84 | D11: =A11 -> Nebraska | E11: =GETPIVOTDATA("Sales",$A$3,"State",A11) -> 2620.84
A12: North Dakota | B12: 891.53 | D12: =A12 -> North Dakota | E12: =GETPIVOTDATA("Sales",$A$3,"State",A12) -> 891.53
A13: Oklahoma | B13: 4467.77 | D13: =A13 -> Oklahoma | E13: =GETPIVOTDATA("Sales",$A$3,"State",A13) -> 4467.77
A14: South Dakota | B14: 45.73 | D14: =A14 -> South Dakota | E14: =GETPIVOTDATA("Sales",$A$3,"State",A14) -> 45.73
A15: Texas | B15: 23550.381 | D15: =A15 -> Texas | E15: =GETPIVOTDATA("Sales",$A$3,"State",A15) -> 23550.381
... A17: Grand Total | B17: 68345.675 | D17: =A17 -> Grand Total | E17: =GETPIVOTDATA("Sales",$A$3,"State",A17) -> #REF!
D18: =A18 -> 0 | E18: =GETPIVOTDATA("Sales",$A$3,"State",A18) -> #REF!
D19: =A19 -> 0 | E19: =GETPIVOTDATA("Sales",$A$3,"State",A19) -> #REF!
D20: =A20 -> 0 | E20: =GETPIVOTDATA("Sales",$A$3,"State",A20) -> #REF!
D21: =A21 -> 0 | E21: =GETPIVOTDATA("Sales",$A$3,"State",A21) -> #REF!
D22: =A22 -> 0 | E22: =GETPIVOTDATA("Sales",$A$3,"State",A22) -> #REF!
D23: =A23 -> 0 | E23: =GETPIVOTDATA("Sales",$A$3,"State",A23) -> #REF!
D24: =A24 -> 0 | E24: =GETPIVOTDATA("Sales",$A$3,"State",A24) -> #REF!
D25: =A25 -> 0 | E25: =GETPIVOTDATA("Sales",$A$3,"State",A25) -> #REF!
D26: =A26 -> 0 | E26: =GETPIVOTDATA("Sales",$A$3,"State",A26) -> #REF!
D27: =A27 -> 0 | E27: =GETPIVOTDATA("Sales",$A$3,"State",A27) -> #REF!
D28: =A28 -> 0 | E28: =GETPIVOTDATA("Sales",$A$3,"State",A28) -> #REF!
D29: =A29 -> 0 | E29: =GETPIVOTDATA("Sales",$A$3,"State",A29) -> #REF!
... D52: =A52 -> 0 | E52: =GETPIVOTDATA("Sales",$A$3,"State",A52) -> #REF!

Sheet Top 5
A3: Row Labels | B3: Sum of Sales
A4: Storage | B4: 6087.646
A5: Tables | B5: 6947.795
A6: Phones | B6: 11301.456
A7: Chairs | B7: 11851.878
A8: Binders | B8: 12149.024
A9: Grand Total | B9: 48337.799

Sheet KPI
A3: Row Labels | B3: Sum of Sales | D3: Row Labels | E3: Sum of Profit | G3: Row Labels | H3: Sum of Quantity | J3: Row Labels | K3: Count of Order ID | M3: Row Labels | N3: Sum of Profit Margin
A4: Jan | B4: 11074.039 | D4: Jan | E4: 2512.7053 | G4: Jan | H4: 124 | J4: Jan | K4: 32 | M4: Jan | N4: 0.22690053
A5: Feb | B5: 1494.19 | D5: Feb | E5: -840.3093 | G5: Feb | H5: 46 | J5: Feb | K5: 14 | M5: Feb | N5: -0.5623845
A6: Mar | B6: 8879.398 | D6: Mar | E6: 1092.1587 | G6: Mar | H6: 109 | J6: Mar | K6: 34 | M6: Mar | N6: 0.12299918
A7: Apr | B7: 2047.026 | D7: Apr | E7: 84.5482 | G7: Apr | H7: 94 | J7: Apr | K7: 23 | M7: Apr | N7: 0.041302944
A8: May | B8: 4069.0664 | D8: May | E8: 438.6879 | G8: May | H8: 103 | J8: May | K8: 33 | M8: May | N8: 0.10781045
A9: Jun | B9: 2818.0252 | D9: Jun | E9: 39.9082 | G9: Jun | H9: 69 | J9: Jun | K9: 22 | M9: Jun | N9: 0.014161761
A10: Jul | B10: 2407.508 | D10: Jul | E10: 317.1642 | G10: Jul | H10: 54 | J10: Jul | K10: 16 | M10: Jul | N10: 0.13173962
A11: Aug | B11: 3083.242 | D11: Aug | E11: 530.3111 | G11: Aug | H11: 95 | J11: Aug | K11: 24 | M11: Aug | N11: 0.17199788
A12: Sep | B12: 5556.877 | D12: Sep | E12: -266.2098 | G12: Sep | H12: 164 | J12: Sep | K12: 44 | M12: Sep | N12: -0.047906369
A13: Oct | B13: 6455.6352 | D13: Oct | E13: 530.1614 | G13: Oct | H13: 120 | J13: Oct | K13: 39 | M13: Oct | N13: 0.082123816
A14: Nov | B14: 6664.5738 | D14: Nov | E14: -2489.0796 | G14: Nov | H14: 210 | J14: Nov | K14: 50 | M14: Nov | N14: -0.37347919
A15: Dec | B15: 13796.095 | D15: Dec | E15: 1030.6896 | G15: Dec | H15: 258 | J15: Dec | K15: 67 | M15: Dec | N15: 0.074708794
A16: Grand Total | B16: 68345.675 | D16: Grand Total | E16: 2980.7359 | G16: Grand Total | H16: 1446 | J16: Grand Total | K16: 398 | M16: Grand Total | N16: 0.043612648
B17: =GETPIVOTDATA("Sales",$A$3) -> 68345.675 | E17: =GETPIVOTDATA("Profit",$D$3) -> 2980.7359 | H17: =GETPIVOTDATA("Quantity",$G$3) -> 1446 | K17: =GETPIVOTDATA("Order ID",$J$3) -> 398 | N17: =GETPIVOTDATA("Profit Margin",$M$3) -> 0.043612648

Sheet KPI YOY
A3: s | B3: Sum of Sales | C3: Sum of Profit | D3: Sum of Quantity | E3: Count of Order ID | F3: Sum of Profit Margin
A4: 2011 | B4: 67316.468 | C4: -1418.8213 | D4: 1039 | E4: 268 | F4: -0.021076883
A5: 2012 | B5: 49662.258 | C5: 1762.3234 | D5: 941 | E5: 247 | F5: 0.035486172
A6: 2013 | B6: 66707.033 | C6: 5239.8101 | D6: 1093 | E6: 299 | F6: 0.07854959
A7: 2014 | B7: 68345.675 | C7: 2980.7359 | D7: 1446 | E7: 398 | F7: 0.043612648
H8: =(GETPIVOTDATA("Sum of Sales",$A$3,"Years (Order Date)",2014)/GETPIVOTDATA("Sum of Sales",$A$3,"Years (Order Date)",2013))-1 -> 0.024564759 | I8: =(GETPIVOTDATA("Sum of Profit",$A$3,"Years (Order Date)",2014)/GETPIVOTDATA("Sum of Profit",$A$3,"Years (Order Date)",2013))-1 -> -0.43113666 | J8: =(GETPIVOTDATA("Sum of Quantity",$A$3,"Years (Order Date)",2014)/GETPIVOTDATA("Sum of Quantity",$A$3,"Years (Order Date)",2013))-1 -> 0.32296432 | K8: =(GETPIVOTDATA("Count of Order ID",$A$3,"Years (Order Date)",2014)/GETPIVOTDATA("Count of Order ID",$A$3,"Years (Order Date)",2013))-1 -> 0.33110368 | L8: =(GETPIVOTDATA("Sum of Profit Margin",$A$3,"Years (Order Date)",2014)/GETPIVOTDATA("Sum of Profit Margin",$A$3,"Years (Order Date)",2013))-1 -> -0.44477561

Sheet DashBoard

Sheet Data
A1: Row ID | B1: Order ID | C1: Year | D1: Order Date | E1: Ship Date | F1: Ship Mode | G1: Customer ID | H1: Customer Name | I1: Segment | J1: Country | K1: City | L1: State | M1: Postal Code | N1: Region | O1: Product ID | P1: Category | Q1: Sub-Category | R1: Product Name | S1: Sales | T1: Quantity | U1: Discount | V1: Profit
A2: 1 | B2: CA-2013-152156 | C2: =YEAR(Data!$D2) -> 2013 | D2: 41587 | E2: 41590 | F2: Second Class | G2: CG-12520 | H2: Claire Gute | I2: Consumer | J2: United States | K2: Henderson | L2: Kentucky | M2: 42420 | N2: South | O2: FUR-BO-10001798 | P2: Furniture | Q2: Bookcases | R2: Bush Somerset Collection Bookcase | S2: 261.96 | T2: 2 | U2: 0 | V2: 41.9136
A3: 2 | B3: CA-2013-152156 | C3: =YEAR(Data!$D3) -> 2013 | D3: 41587 | E3: 41590 | F3: Second Class | G3: CG-12520 | H3: Claire Gute | I3: Consumer | J3: United States | K3: Henderson | L3: Kentucky | M3: 42420 | N3: South | O3: FUR-CH-10000454 | P3: Furniture | Q3: Chairs | R3: Hon Deluxe Fabric Upholstered Stacking Chairs, Rounded Back | S3: 731.94 | T3: 3 | U3: 0 | V3: 219.582
A4: 3 | B4: CA-2013-138688 | C4: =YEAR(Data!$D4) -> 2013 | D4: 41438 | E4: 41442 | F4: Second Class | G4: DV-13045 | H4: Darrin Van Huff | I4: Corporate | J4: United States | K4: Los Angeles | L4: California | M4: 90036 | N4: West | O4: OFF-LA-10000240 | P4: Office Supplies | Q4: Labels | R4: Self-Adhesive Address Labels for Typewriters by Universal | S4: 14.62 | T4: 2 | U4: 0 | V4: 6.8714
A5: 4 | B5: US-2012-108966 | C5: =YEAR(Data!$D5) -> 2012 | D5: 41193 | E5: 41200 | F5: Standard Class | G5: SO-20335 | H5: Sean O'Donnell | I5: Consumer | J5: United States | K5: Fort Lauderdale | L5: Florida | M5: 33311 | N5: South | O5: FUR-TA-10000577 | P5: Furniture | Q5: Tables | R5: Bretford CR4500 Series Slim Rectangular Table | S5: 957.5775 | T5: 5 | U5: 0.45 | V5: -383.031
A6: 5 | B6: US-2012-108966 | C6: =YEAR(Data!$D6) -> 2012 | D6: 41193 | E6: 41200 | F6: Standard Class | G6: SO-20335 | H6: Sean O'Donnell | I6: Consumer | J6: United States | K6: Fort Lauderdale | L6: Florida | M6: 33311 | N6: South | O6: OFF-ST-10000760 | P6: Office Supplies | Q6: Storage | R6: Eldon Fold 'N Roll Cart System | S6: 22.368 | T6: 2 | U6: 0.2 | V6: 2.5164
A7: 6 | B7: CA-2011-115812 | C7: =YEAR(Data!$D7) -> 2011 | D7: 40703 | E7: 40708 | F7: Standard Class | G7: BH-11710 | H7: Brosina Hoffman | I7: Consumer | J7: United States | K7: Los Angeles | L7: California | M7: 90032 | N7: West | O7: FUR-FU-10001487 | P7: Furniture | Q7: Furnishings | R7: Eldon Expressions Wood and Plastic Desk Accessories, Cherry Wood | S7: 48.86 | T7: 7 | U7: 0 | V7: 14.1694
A8: 7 | B8: CA-2011-115812 | C8: =YEAR(Data!$D8) -> 2011 | D8: 40703 | E8: 40708 | F8: Standard Class | G8: BH-11710 | H8: Brosina Hoffman | I8: Consumer | J8: United States | K8: Los Angeles | L8: California | M8: 90032 | N8: West | O8: OFF-AR-10002833 | P8: Office Supplies | Q8: Art | R8: Newell 322 | S8: 7.28 | T8: 4 | U8: 0 | V8: 1.9656
A9: 8 | B9: CA-2011-115812 | C9: =YEAR(Data!$D9) -> 2011 | D9: 40703 | E9: 40708 | F9: Standard Class | G9: BH-11710 | H9: Brosina Hoffman | I9: Consumer | J9: United States | K9: Los Angeles | L9: California | M9: 90032 | N9: West | O9: TEC-PH-10002275 | P9: Technology | Q9: Phones | R9: Mitel 5320 IP Phone VoIP phone | S9: 907.152 | T9: 6 | U9: 0.2 | V9: 90.7152
A10: 9 | B10: CA-2011-115812 | C10: =YEAR(Data!$D10) -> 2011 | D10: 40703 | E10: 40708 | F10: Standard Class | G10: BH-11710 | H10: Brosina Hoffman | I10: Consumer | J10: United States | K10: Los Angeles | L10: California | M10: 90032 | N10: West | O10: OFF-BI-10003910 | P10: Office Supplies | Q10: Binders | R10: DXL Angle-View Binders with Locking Rings by Samsill | S10: 18.504 | T10: 3 | U10: 0.2 | V10: 5.7825
A11: 10 | B11: CA-2011-115812 | C11: =YEAR(Data!$D11) -> 2011 | D11: 40703 | E11: 40708 | F11: Standard Class | G11: BH-11710 | H11: Brosina Hoffman | I11: Consumer | J11: United States | K11: Los Angeles | L11: California | M11: 90032 | N11: West | O11: OFF-AP-10002892 | P11: Office Supplies | Q11: Appliances | R11: Belkin F5C206VTEL 6 Outlet Surge | S11: 114.9 | T11: 5 | U11: 0 | V11: 34.47
A12: 11 | B12: CA-2011-115812 | C12: =YEAR(Data!$D12) -> 2011 | D12: 40703 | E12: 40708 | F12: Standard Class | G12: BH-11710 | H12: Brosina Hoffman | I12: Consumer | J12: United States | K12: Los Angeles | L12: California | M12: 90032 | N12: West | O12: FUR-TA-10001539 | P12: Furniture | Q12: Tables | R12: Chromcraft Rectangular Conference Tables | S12: 1706.184 | T12: 9 | U12: 0.2 | V12: 85.3092
A13: 12 | B13: CA-2011-115812 | C13: =YEAR(Data!$D13) -> 2011 | D13: 40703 | E13: 40708 | F13: Standard Class | G13: BH-11710 | H13: Brosina Hoffman | I13: Consumer | J13: United States | K13: Los Angeles | L13: California | M13: 90032 | N13: West | O13: TEC-PH-10002033 | P13: Technology | Q13: Phones | R13: Konftel 250 Conference phone - Charcoal black | S13: 911.424 | T13: 4 | U13: 0.2 | V13: 68.3568
... A2235: 2234 | B2235: CA-2012-123232 | C2235: =YEAR(Data!$D2235) -> 2012 | D2235: 41257 | E2235: 41259 | F2235: Second Class | G2235: DJ-13630 | H2235: Doug Jacobs | I2235: Consumer | J2235: United States | K2235: Portland | L2235: Oregon | M2235: 97206 | N2235: West | O2235: TEC-PH-10001051 | P2235: Technology | Q2235: Phones | R2235: HTC One | S2235: 319.968 | T2235: 4 | U2235: 0.2 | V2235: 35.9964
A2236: 2235 | B2236: CA-2014-104066 | C2236: =YEAR(Data!$D2236) -> 2014 | D2236: 41979 | E2236: 41984 | F2236: Standard Class | G2236: QJ-19255 | H2236: Quincy Jones | I2236: Corporate | J2236: United States | K2236: Burlington | L2236: Vermont | M2236: 05408 | N2236: East | O2236: TEC-AC-10001013 | P2236: Technology | Q2236: Accessories | R2236: Logitech ClearChat Comfort/USB Headset H390 | S2236: 205.03 | T2236: 7 | U2236: 0 | V2236: 67.6599
A2237: 2236 | B2237: CA-2012-145849 | C2237: =YEAR(Data!$D2237) -> 2012 | D2237: 41167 | E2237: 41169 | F2237: Second Class | G2237: CT-11995 | H2237: Carol Triggs | I2237: Consumer | J2237: United States | K2237: Indianapolis | L2237: Indiana | M2237: 46203 | N2237: Central | O2237: OFF-ST-10000025 | P2237: Office Supplies | Q2237: Storage | R2237: Fellowes Stor/Drawer Steel Plus Storage Drawers | S2237: 190.86 | T2237: 2 | U2237: 0 | V2237: 11.4516
A2238: 2237 | B2238: CA-2012-145849 | C2238: =YEAR(Data!$D2238) -> 2012 | D2238: 41167 | E2238: 41169 | F2238: Second Class | G2238: CT-11995 | H2238: Carol Triggs | I2238: Consumer | J2238: United States | K2238: Indianapolis | L2238: Indiana | M2238: 46203 | N2238: Central | O2238: OFF-AR-10000817 | P2238: Office Supplies | Q2238: Art | R2238: Manco Dry-Lighter Erasable Highlighter | S2238: 24.32 | T2238: 8 | U2238: 0 | V2238: 8.2688
A2239: 2238 | B2239: CA-2013-122322 | C2239: =YEAR(Data!$D2239) -> 2013 | D2239: 41471 | E2239: 41477 | F2239: Standard Class | G2239: RH-19510 | H2239: Rick Huthwaite | I2239: Home Office | J2239: United States | K2239: Provo | L2239: Utah | M2239: 84604 | N2239: West | O2239: OFF-SU-10000952 | P2239: Office Supplies | Q2239: Supplies | R2239: Fiskars Home & Office Scissors | S2239: 44.4 | T2239: 5 | U2239: 0 | V2239: 12.432
A2240: 2239 | B2240: CA-2014-166849 | C2240: =YEAR(Data!$D2240) -> 2014 | D2240: 41750 | E2240: 41756 | F2240: Standard Class | G2240: SJ-20125 | H2240: Sanjit Jacobs | I2240: Home Office | J2240: United States | K2240: Chicago | L2240: Illinois | M2240: 60610 | N2240: Central | O2240: FUR-FU-10004597 | P2240: Furniture | Q2240: Furnishings | R2240: Eldon Cleatmat Chair Mats for Medium Pile Carpets | S2240: 44.4 | T2240: 2 | U2240: 0.6 | V2240: -52.17
A2241: 2240 | B2241: CA-2013-146633 | C2241: =YEAR(Data!$D2241) -> 2013 | D2241: 41594 | E2241: 41596 | F2241: Second Class | G2241: TG-21310 | H2241: Toby Gnade | I2241: Consumer | J2241: United States | K2241: Los Angeles | L2241: California | M2241: 90049 | N2241: West | O2241: OFF-BI-10003527 | P2241: Office Supplies | Q2241: Binders | R2241: Fellowes PB500 Electric Punch Plastic Comb Binding Machine with Manual Bind | S2241: 1016.792 | T2241: 1 | U2241: 0.2 | V2241: 381.297
A2242: 2241 | B2242: CA-2013-146633 | C2242: =YEAR(Data!$D2242) -> 2013 | D2242: 41594 | E2242: 41596 | F2242: Second Class | G2242: TG-21310 | H2242: Toby Gnade | I2242: Consumer | J2242: United States | K2242: Los Angeles | L2242: California | M2242: 90049 | N2242: West | O2242: OFF-BI-10002982 | P2242: Office Supplies | Q2242: Binders | R2242: Avery Self-Adhesive Photo Pockets for Polaroid Photos | S2242: 38.136 | T2242: 7 | U2242: 0.2 | V2242: 13.3476
A2243: 2242 | B2243: US-2013-126893 | C2243: =YEAR(Data!$D2243) -> 2013 | D2243: 41605 | E2243: 41610 | F2243: Standard Class | G2243: CT-11995 | H2243: Carol Triggs | I2243: Consumer | J2243: United States | K2243: Philadelphia | L2243: Pennsylvania | M2243: 19134 | N2243: East | O2243: TEC-PH-10004165 | P2243: Technology | Q2243: Phones | R2243: Mitel MiVoice 5330e IP Phone | S2243: 494.982 | T2243: 3 | U2243: 0.4 | V2243: -115.4958
A2244: 2243 | B2244: CA-2014-103380 | C2244: =YEAR(Data!$D2244) -> 2014 | D2244: 41965 | E2244: 41969 | F2244: Standard Class | G2244: BF-11005 | H2244: Barry Franz | I2244: Home Office | J2244: United States | K2244: Pasadena | L2244: California | M2244: 91104 | N2244: West | O2244: OFF-ST-10003442 | P2244: Office Supplies | Q2244: Storage | R2244: Eldon Portable Mobile Manager | S2244: 56.56 | T2244: 2 | U2244: 0 | V2244: 15.2712
A2245: 2244 | B2245: CA-2014-103380 | C2245: =YEAR(Data!$D2245) -> 2014 | D2245: 41965 | E2245: 41969 | F2245: Standard Class | G2245: BF-11005 | H2245: Barry Franz | I2245: Home Office | J2245: United States | K2245: Pasadena | L2245: California | M2245: 91104 | N2245: West | O2245: OFF-AR-10003856 | P2245: Office Supplies | Q2245: Art | R2245: Newell 344 | S2245: 5.56 | T2245: 2 | U2245: 0 | V2245: 1.4456
A2246: 2245 | B2246: CA-2014-103380 | C2246: =YEAR(Data!$D2246) -> 2014 | D2246: 41965 | E2246: 41969 | F2246: Standard Class | G2246: BF-11005 | H2246: Barry Franz | I2246: Home Office | J2246: United States | K2246: Pasadena | L2246: California | M2246: 91104 | N2246: West | O2246: OFF-FA-10004248 | P2246: Office Supplies | Q2246: Fasteners | R2246: Advantus T-Pin Paper Clips | S2246: 9.02 | T2246: 2 | U2246: 0 | V2246: 3.5178
A2247: 2246 | B2247: CA-2014-103380 | C2247: =YEAR(Data!$D2247) -> 2014 | D2247: 41965 | E2247: 41969 | F2247: Standard Class | G2247: BF-11005 | H2247: Barry Franz | I2247: Home Office | J2247: United States | K2247: Pasadena | L2247: California | M2247: 91104 | N2247: West | O2247: OFF-AP-10001492 | P2247: Office Supplies | Q2247: Appliances | R2247: Acco Six-Outlet Power Strip, 4' Cord Length | S2247: 8.62 | T2247: 1 | U2247: 0 | V2247: 2.2412
A2248: 2247 | B2248: CA-2014-103380 | C2248: =YEAR(Data!$D2248) -> 2014 | D2248: 41965 | E2248: 41969 | F2248: Standard Class | G2248: BF-11005 | H2248: Barry Franz | I2248: Home Office | J2248: United States | K2248: Pasadena | L2248: California | M2248: 91104 | N2248: West | O2248: TEC-PH-10004165 | P2248: Technology | Q2248: Phones | R2248: Mitel MiVoice 5330e IP Phone | S2248: 659.976 | T2248: 3 | U2248: 0.2 | V2248: 49.4982
... A5275: 5274 | B5275: US-2013-158309 | C5275: =YEAR(Data!$D5275) -> 2013 | D5275: 41605 | E5275: 41608 | F5275: First Class | G5275: PA-19060 | H5275: Pete Armstrong | I5275: Home Office | J5275: United States | K5275: Miami | L5275: Florida | M5275: 33142 | N5275: South | O5275: OFF-BI-10000145 | P5275: Office Supplies | Q5275: Binders | R5275: Zipper Ring Binder Pockets | S5275: 3.744 | T5275: 4 | U5275: 0.7 | V5275: -2.6208
A5276: 5275 | B5276: CA-2012-162887 | C5276: =YEAR(Data!$D5276) -> 2012 | D5276: 41220 | E5276: 41222 | F5276: Second Class | G5276: SV-20785 | H5276: Stewart Visinsky | I5276: Consumer | J5276: United States | K5276: Burlington | L5276: Vermont | M5276: 05408 | N5276: East | O5276: FUR-CH-10000595 | P5276: Furniture | Q5276: Chairs | R5276: Safco Contoured Stacking Chairs | S5276: 715.2 | T5276: 3 | U5276: 0 | V5276: 178.8
A5277: 5276 | B5277: CA-2014-147333 | C5277: =YEAR(Data!$D5277) -> 2014 | D5277: 41988 | E5277: 41994 | F5277: Standard Class | G5277: KL-16555 | H5277: Kelly Lampkin | I5277: Corporate | J5277: United States | K5277: Fayetteville | L5277: Arkansas | M5277: 72701 | N5277: South | O5277: TEC-AC-10004469 | P5277: Technology | Q5277: Accessories | R5277: Microsoft Sculpt Comfort Mouse | S5277: 159.8 | T5277: 4 | U5277: 0 | V5277: 70.312
A5278: 5277 | B5278: CA-2014-147333 | C5278: =YEAR(Data!$D5278) -> 2014 | D5278: 41988 | E5278: 41994 | F5278: Standard Class | G5278: KL-16555 | H5278: Kelly Lampkin | I5278: Corporate | J5278: United States | K5278: Fayetteville | L5278: Arkansas | M5278: 72701 | N5278: South | O5278: TEC-AC-10003038 | P5278: Technology | Q5278: Accessories | R5278: Kingston Digital DataTraveler 16GB USB 2.0 | S5278: 44.75 | T5278: 5 | U5278: 0 | V5278: 8.5025
A5279: 5278 | B5279: CA-2011-113859 | C5279: =YEAR(Data!$D5279) -> 2011 | D5279: 40799 | E5279: 40803 | F5279: Standard Class | G5279: BC-11125 | H5279: Becky Castell | I5279: Home Office | J5279: United States | K5279: Odessa | L5279: Texas | M5279: 79762 | N5279: Central | O5279: FUR-CH-10004698 | P5279: Furniture | Q5279: Chairs | R5279: Padded Folding Chairs, Black, 4/Carton | S5279: 340.116 | T5279: 6 | U5279: 0.3 | V5279: -9.7176
A5280: 5279 | B5280: CA-2011-159681 | C5280: =YEAR(Data!$D5280) -> 2011 | D5280: 40884 | E5280: 40890 | F5280: Standard Class | G5280: PO-18850 | H5280: Patrick O'Brill | I5280: Consumer | J5280: United States | K5280: Virginia Beach | L5280: Virginia | M5280: 23464 | N5280: South | O5280: OFF-PA-10003641 | P5280: Office Supplies | Q5280: Paper | R5280: Xerox 1909 | S5280: 105.52 | T5280: 4 | U5280: 0 | V5280: 48.5392
A5281: 5280 | B5281: US-2014-104094 | C5281: =YEAR(Data!$D5281) -> 2014 | D5281: 41890 | E5281: 41894 | F5281: Standard Class | G5281: AG-10675 | H5281: Anna Gayman | I5281: Consumer | J5281: United States | K5281: Milwaukee | L5281: Wisconsin | M5281: 53209 | N5281: Central | O5281: TEC-AC-10002134 | P5281: Technology | Q5281: Accessories | R5281: Rosewill 107 Normal Keys USB Wired Standard Keyboard | S5281: 13.48 | T5281: 1 | U5281: 0 | V5281: 1.8872
A5282: 5281 | B5282: CA-2014-152709 | C5282: =YEAR(Data!$D5282) -> 2014 | D5282: 41920 | E5282: 41925 | F5282: Standard Class | G5282: DB-13210 | H5282: Dean Braden | I5282: Consumer | J5282: United States | K5282: Detroit | L5282: Michigan | M5282: 48234 | N5282: Central | O5282: OFF-ST-10001837 | P5282: Office Supplies | Q5282: Storage | R5282: SAFCO Mobile Desk Side File, Wire Frame | S5282: 85.52 | T5282: 2 | U5282: 0 | V5282: 22.2352
A5283: 5282 | B5283: CA-2012-105158 | C5283: =YEAR(Data!$D5283) -> 2012 | D5283: 41157 | E5283: 41162 | F5283: Standard Class | G5283: SP-20860 | H5283: Sung Pak | I5283: Corporate | J5283: United States | K5283: Rochester | L5283: Minnesota | M5283: 55901 | N5283: Central | O5283: FUR-FU-10001706 | P5283: Furniture | Q5283: Furnishings | R5283: Longer-Life Soft White Bulbs | S5283: 6.16 | T5283: 2 | U5283: 0 | V5283: 2.9568
A5284: 5283 | B5284: CA-2012-105158 | C5284: =YEAR(Data!$D5284) -> 2012 | D5284: 41157 | E5284: 41162 | F5284: Standard Class | G5284: SP-20860 | H5284: Sung Pak | I5284: Corporate | J5284: United States | K5284: Rochester | L5284: Minnesota | M5284: 55901 | N5284: Central | O5284: OFF-PA-10001970 | P5284: Office Supplies | Q5284: Paper | R5284: Xerox 1881 | S5284: 36.84 | T5284: 3 | U5284: 0 | V5284: 17.3148
A5285: 5284 | B5285: CA-2011-133424 | C5285: =YEAR(Data!$D5285) -> 2011 | D5285: 40632 | E5285: 40637 | F5285: Standard Class | G5285: Dl-13600 | H5285: Dorris liebe | I5285: Corporate | J5285: United States | K5285: Seattle | L5285: Washington | M5285: 98105 | N5285: West | O5285: OFF-ST-10002957 | P5285: Office Supplies | Q5285: Storage | R5285: Sterilite Show Offs Storage Containers | S5285: 15.84 | T5285: 3 | U5285: 0 | V5285: 0
A5286: 5285 | B5286: CA-2011-133424 | C5286: =YEAR(Data!$D5286) -> 2011 | D5286: 40632 | E5286: 40637 | F5286: Standard Class | G5286: Dl-13600 | H5286: Dorris liebe | I5286: Corporate | J5286: United States | K5286: Seattle | L5286: Washington | M5286: 98105 | N5286: West | O5286: OFF-LA-10002312 | P5286: Office Supplies | Q5286: Labels | R5286: Avery 490 | S5286: 44.4 | T5286: 3 | U5286: 0 | V5286: 22.2
A5287: 5286 | B5287: CA-2014-105991 | C5287: =YEAR(Data!$D5287) -> 2014 | D5287: 41765 | E5287: 41766 | F5287: First Class | G5287: LH-17020 | H5287: Lisa Hazard | I5287: Consumer | J5287: United States | K5287: Louisville | L5287: Colorado | M5287: 80027 | N5287: West | O5287: OFF-EN-10002600 | P5287: Office Supplies | Q5287: Envelopes | R5287: Redi-Strip #10 Envelopes, 4 1/8 x 9 1/2 | S5287: 21.24 | T5287: 9 | U5287: 0.2 | V5287: 7.434
...

Sheet layout
A11: `` | B11: =#REF! -> #REF!
